Workbook
Name UPDATE: 'Data Sheet'!$E$1

Sheet Profit & Loss
A1: ='Data Sheet'!B1 -> HINDUSTAN UNILEVER LTD | H1: =UPDATE | M1: SCREENER.IN
A3: Narration | B3: ='Data Sheet'!B16 -> 42825 | C3: ='Data Sheet'!C16 -> 43190 | D3: ='Data Sheet'!D16 -> 43555 | E3: ='Data Sheet'!E16 -> 43921 | F3: ='Data Sheet'!F16 -> 44286 | G3: ='Data Sheet'!G16 -> 44651 | H3: ='Data Sheet'!H16 -> 45016 | I3: ='Data Sheet'!I16 -> 45382 | ... K3: ='Data Sheet'!K16 -> 46112 | L3: Trailing | M3: Best Case | N3: Worst Case
A4: Sales | B4: ='Data Sheet'!B17 -> 33162 | C4: ='Data Sheet'!C17 -> 35545 | D4: ='Data Sheet'!D17 -> 39310 | E4: ='Data Sheet'!E17 -> 39783 | F4: ='Data Sheet'!F17 -> 47028 | G4: ='Data Sheet'!G17 -> 52446 | H4: ='Data Sheet'!H17 -> 60580 | I4: ='Data Sheet'!I17 -> 61896 | ... K4: ='Data Sheet'!K17 -> 64468 | L4: =SUM(Quarters!H4:K4) -> 65225 | M4: =$K4+M23*K4 -> 65843.745 | N4: =$K4+N23*L4 -> 65834.541
A5: Expenses | B5: =SUM('Data Sheet'!B18,'Data Sheet'!B20:B24,-1*'Data Sheet'!B19) -> 26834 | C5: =SUM('Data Sheet'!C18,'Data Sheet'!C20:C24,-1*'Data Sheet'!C19) -> 28046 | D5: =SUM('Data Sheet'!D18,'Data Sheet'!D20:D24,-1*'Data Sheet'!D19) -> 30430 | E5: =SUM('Data Sheet'!E18,'Data Sheet'!E20:E24,-1*'Data Sheet'!E19) -> 29922 | F5: =SUM('Data Sheet'!F18,'Data Sheet'!F20:F24,-1*'Data Sheet'!F19) -> 35402 | G5: =SUM('Data Sheet'!G18,'Data Sheet'!G20:G24,-1*'Data Sheet'!G19) -> 39589 | H5: =SUM('Data Sheet'!H18,'Data Sheet'!H20:H24,-1*'Data Sheet'!H19) -> 46433 | I5: =SUM('Data Sheet'!I18,'Data Sheet'!I20:I24,-1*'Data Sheet'!I19) -> 47237 | ... K5: =SUM('Data Sheet'!K18,'Data Sheet'!K20:K24,-1*'Data Sheet'!K19) -> 49429 | L5: =SUM(Quarters!H5:K5) -> 50108 | M5: =M4-M6 -> 50366.286 | N5: =N4-N6 -> 50576.269
A6: Operating Profit | B6: =B4-B5 -> 6328 | C6: =C4-C5 -> 7499 | D6: =D4-D5 -> 8880 | E6: =E4-E5 -> 9861 | F6: =F4-F5 -> 11626 | G6: =G4-G5 -> 12857 | H6: =H4-H5 -> 14147 | I6: =I4-I5 -> 14659 | ... K6: =K4-K5 -> 15039 | L6: =SUM(Quarters!H6:K6) -> 15117 | M6: =M4*M24 -> 15477.459 | N6: =N4*N24 -> 15258.271
A7: Other Income | B7: ='Data Sheet'!B25 -> 606 | C7: ='Data Sheet'!C25 -> 353 | D7: ='Data Sheet'!D25 -> 322 | E7: ='Data Sheet'!E25 -> 424 | F7: ='Data Sheet'!F25 -> 170 | G7: ='Data Sheet'!G25 -> 219 | H7: ='Data Sheet'!H25 -> 448 | I7: ='Data Sheet'!I25 -> 817 | ... K7: ='Data Sheet'!K25 -> 4923 | L7: =SUM(Quarters!H7:K7) -> 4894 | M7: 0 | N7: 0
A8: Depreciation | B8: ='Data Sheet'!B26 -> 432 | C8: ='Data Sheet'!C26 -> 520 | D8: ='Data Sheet'!D26 -> 565 | E8: ='Data Sheet'!E26 -> 1002 | F8: ='Data Sheet'!F26 -> 1074 | G8: ='Data Sheet'!G26 -> 1091 | H8: ='Data Sheet'!H26 -> 1137 | I8: ='Data Sheet'!I26 -> 1216 | ... K8: ='Data Sheet'!K26 -> 1333 | L8: =SUM(Quarters!H8:K8) -> 1368 | M8: =+$L8 -> 1368 | N8: =+$L8 -> 1368
A9: Interest | B9: ='Data Sheet'!B27 -> 35 | C9: ='Data Sheet'!C27 -> 26 | D9: ='Data Sheet'!D27 -> 33 | E9: ='Data Sheet'!E27 -> 118 | F9: ='Data Sheet'!F27 -> 117 | G9: ='Data Sheet'!G27 -> 106 | H9: ='Data Sheet'!H27 -> 114 | I9: ='Data Sheet'!I27 -> 334 | ... K9: ='Data Sheet'!K27 -> 410 | L9: =SUM(Quarters!H9:K9) -> 415 | M9: =+$L9 -> 415 | N9: =+$L9 -> 415
A10: Profit before tax | B10: ='Data Sheet'!B28 -> 6467 | C10: ='Data Sheet'!C28 -> 7306 | D10: ='Data Sheet'!D28 -> 8604 | E10: ='Data Sheet'!E28 -> 9165 | F10: ='Data Sheet'!F28 -> 10605 | G10: ='Data Sheet'!G28 -> 11879 | H10: ='Data Sheet'!H28 -> 13344 | I10: ='Data Sheet'!I28 -> 13926 | ... K10: ='Data Sheet'!K28 -> 18219 | L10: =SUM(Quarters!H10:K10) -> 18228 | M10: =M6+M7-SUM(M8:M9) -> 13694.459 | N10: =N6+N7-SUM(N8:N9) -> 13475.271
A11: Tax | B11: ='Data Sheet'!B29 -> 1977 | C11: ='Data Sheet'!C29 -> 2079 | D11: ='Data Sheet'!D29 -> 2544 | E11: ='Data Sheet'!E29 -> 2409 | F11: ='Data Sheet'!F29 -> 2606 | G11: ='Data Sheet'!G29 -> 2987 | H11: ='Data Sheet'!H29 -> 3201 | I11: ='Data Sheet'!I29 -> 3644 | ... K11: ='Data Sheet'!K29 -> 3160 | L11: =SUM(Quarters!H11:K11) -> 3169 | M11: =IF($L10>0,$L11/$L10,0) -> 0.17385341 | N11: =IF($L10>0,$L11/$L10,0) -> 0.17385341
A12: Net profit | B12: ='Data Sheet'!B30 -> 4476 | C12: ='Data Sheet'!C30 -> 5214 | D12: ='Data Sheet'!D30 -> 6054 | E12: ='Data Sheet'!E30 -> 6748 | F12: ='Data Sheet'!F30 -> 7995 | G12: ='Data Sheet'!G30 -> 8879 | H12: ='Data Sheet'!H30 -> 10120 | I12: ='Data Sheet'!I30 -> 10277 | ... K12: ='Data Sheet'!K30 -> 15040 | L12: =SUM(Quarters!H12:K12) -> 15040 | M12: =M10-M11*M10 -> 11313.63 | N12: =N10-N11*N10 -> 11132.55
A13: EPS | B13: =IF('Data Sheet'!B124>0,B12/'Data Sheet'!B124,0) -> 20.681052 | C13: =IF('Data Sheet'!C124>0,C12/'Data Sheet'!C124,0) -> 24.088704 | D13: =IF('Data Sheet'!D124>0,D12/'Data Sheet'!D124,0) -> 27.966924 | E13: =IF('Data Sheet'!E124>0,E12/'Data Sheet'!E124,0) -> 31.171471 | F13: =IF('Data Sheet'!F124>0,F12/'Data Sheet'!F124,0) -> 34.027068 | G13: =IF('Data Sheet'!G124>0,G12/'Data Sheet'!G124,0) -> 37.789411 | H13: =IF('Data Sheet'!H124>0,H12/'Data Sheet'!H124,0) -> 43.071161 | I13: =IF('Data Sheet'!I124>0,I12/'Data Sheet'!I124,0) -> 43.73936 | ... K13: =IF('Data Sheet'!K124>0,K12/'Data Sheet'!K124,0) -> 64.010895 | L13: =IF('Data Sheet'!$B6>0,'Profit & Loss'!L12/'Data Sheet'!$B6,0) -> 63.964656 | M13: =IF('Data Sheet'!$B6>0,'Profit & Loss'!M12/'Data Sheet'!$B6,0) -> 48.11652 | N13: =IF('Data Sheet'!$B6>0,'Profit & Loss'!N12/'Data Sheet'!$B6,0) -> 47.34639
A14: Price to earning | B14: =IF(B15>0,B15/B13,"") -> 42.193696 | C14: =IF(C15>0,C15/C13,"") -> 52.975453 | D14: =IF(D15>0,D15/D13,"") -> 58.409356 | E14: =IF(E15>0,E15/E13,"") -> 70.571903 | F14: =IF(F15>0,F15/F13,"") -> 68.390258 | G14: =IF(G15>0,G15/G13,"") -> 51.884905 | H14: =IF(H15>0,H15/H13,"") -> 56.892824 | I14: =IF(I15>0,I15/I13,"") -> 49.546678 | ... K14: =IF(K15>0,K15/K13,"") -> 32.107034 | L14: =IF(L13>0,L15/L13,0) -> 34.354128 | M14: =M25 -> 40.926914 | N14: =N25 -> 34.354128
A15: Price | B15: ='Data Sheet'!B121 -> 872.61 | C15: ='Data Sheet'!C121 -> 1276.11 | D15: ='Data Sheet'!D121 -> 1633.53 | E15: ='Data Sheet'!E121 -> 2199.83 | F15: ='Data Sheet'!F121 -> 2327.12 | G15: ='Data Sheet'!G121 -> 1960.7 | H15: ='Data Sheet'!H121 -> 2450.44 | I15: ='Data Sheet'!I121 -> 2167.14 | ... K15: ='Data Sheet'!K121 -> 2055.2 | L15: ='Data Sheet'!B8 -> 2197.45 | M15: =M13*M14 -> 1969.2607 | N15: =N13*N14 -> 1626.5439
A17: RATIOS:
A18: Dividend Payout | B18: =IF('Data Sheet'!B30>0,'Data Sheet'!B31/'Data Sheet'!B30,0) -> 0.82037534 | C18: =IF('Data Sheet'!C30>0,'Data Sheet'!C31/'Data Sheet'!C30,0) -> 0.82853855 | D18: =IF('Data Sheet'!D30>0,'Data Sheet'!D31/'Data Sheet'!D30,0) -> 0.78493558 | E18: =IF('Data Sheet'!E30>0,'Data Sheet'!E31/'Data Sheet'!E30,0) -> 0.80023711 | F18: =IF('Data Sheet'!F30>0,'Data Sheet'!F31/'Data Sheet'!F30,0) -> 1.1904315 | G18: =IF('Data Sheet'!G30>0,'Data Sheet'!G31/'Data Sheet'!G30,0) -> 0.89987611 | H18: =IF('Data Sheet'!H30>0,'Data Sheet'!H31/'Data Sheet'!H30,0) -> 0.90563241 | I18: =IF('Data Sheet'!I30>0,'Data Sheet'!I31/'Data Sheet'!I30,0) -> 0.960397 | ... K18: =IF('Data Sheet'!K30>0,'Data Sheet'!K31/'Data Sheet'!K30,0) -> 0.640625
A19: OPM | B19: =IF(B6>0,B6/B4,0) -> 0.19082082 | C19: =IF(C6>0,C6/C4,0) -> 0.21097201 | D19: =IF(D6>0,D6/D4,0) -> 0.22589672 | E19: =IF(E6>0,E6/E4,0) -> 0.24786969 | F19: =IF(F6>0,F6/F4,0) -> 0.24721443 | G19: =IF(G6>0,G6/G4,0) -> 0.24514739 | H19: =IF(H6>0,H6/H4,0) -> 0.23352592 | I19: =IF(I6>0,I6/I4,0) -> 0.23683275 | ... L19: =IF(L6>0,L6/L4,0) -> 0.23176696
G22: TRENDS: | H22: 10 YEARS | I22: 7 YEARS | J22: 5 YEARS | K22: 3 YEARS | L22: RECENT | M22: BEST | N22: WORST
G23: Sales Growth | H23: =IF(B4=0,"",POWER($K4/B4,1/9)-1) -> 0.076658974 | I23: =IF(D4=0,"",POWER($K4/D4,1/7)-1) -> 0.073227008 | J23: =IF(F4=0,"",POWER($K4/F4,1/5)-1) -> 0.065117542 | K23: =IF(H4=0,"",POWER($K4/H4,1/3)-1) -> 0.020951182 | L23: =IF(ISERROR(MAX(IF(J4=0,"",(K4-J4)/J4),IF(K4=0,"",(L4-K4)/K4))),"",MAX(IF(J4=0,"",(K4-J4)/J4),IF(K4=0,"",(L4-K4)/K4))) -> 0.021339966 | M23: =MAX(K23:L23) -> 0.021339966 | N23: =MIN(H23:L23) -> 0.020951182
G24: OPM | H24: =IF(SUM(B4:$K$4)=0,"",SUMPRODUCT(B19:$K$19,B4:$K$4)/SUM(B4:$K$4)) -> 0.23271652 | I24: =IF(SUM(E4:$K$4)=0,"",SUMPRODUCT(E19:$K$19,E4:$K$4)/SUM(E4:$K$4)) -> 0.23895901 | J24: =IF(SUM(G4:$K$4)=0,"",SUMPRODUCT(G19:$K$19,G4:$K$4)/SUM(G4:$K$4)) -> 0.2365038 | K24: =IF(SUM(I4:$K$4)=0,"",SUMPRODUCT(I19:$K$19,I4:$K$4)/SUM(I4:$K$4)) -> 0.23506346 | L24: =L19 -> 0.23176696 | M24: =MAX(K24:L24) -> 0.23506346 | N24: =MIN(H24:L24) -> 0.23176696
G25: Price to Earning | H25: =IF(ISERROR(AVERAGEIF(B14:$L14,">0")),"",AVERAGEIF(B14:$L14,">0")) -> 51.366005 | I25: =IF(ISERROR(AVERAGEIF(E14:$L14,">0")),"",AVERAGEIF(E14:$L14,">0")) -> 51.430943 | J25: =IF(ISERROR(AVERAGEIF(G14:$L14,">0")),"",AVERAGEIF(G14:$L14,">0")) -> 45.414231 | K25: =IF(ISERROR(AVERAGEIF(I14:$L14,">0")),"",AVERAGEIF(I14:$L14,">0")) -> 40.926914 | L25: =L14 -> 34.354128 | M25: =MAX(K25:L25) -> 40.926914 | N25: =MIN(H25:L25) -> 34.354128

Sheet Quarters
A1: ='Profit & Loss'!A1 -> HINDUSTAN UNILEVER LTD | E1: =UPDATE | J1: SCREENER.IN
A3: Narration | B3: ='Data Sheet'!B41 -> 45291 | C3: ='Data Sheet'!C41 -> 45382 | D3: ='Data Sheet'!D41 -> 45473 | E3: ='Data Sheet'!E41 -> 45565 | F3: ='Data Sheet'!F41 -> 45657 | G3: ='Data Sheet'!G41 -> 45747 | H3: ='Data Sheet'!H41 -> 45838 | I3: ='Data Sheet'!I41 -> 45930 | ... K3: ='Data Sheet'!K41 -> 46112
A4: Sales | B4: ='Data Sheet'!B42 -> 15567 | C4: ='Data Sheet'!C42 -> 15210 | D4: ='Data Sheet'!D42 -> 15707 | E4: ='Data Sheet'!E42 -> 15926 | F4: ='Data Sheet'!F42 -> 15556 | G4: ='Data Sheet'!G42 -> 15190 | H4: ='Data Sheet'!H42 -> 16514 | I4: ='Data Sheet'!I42 -> 15919 | ... K4: ='Data Sheet'!K42 -> 16351
A5: Expenses | B5: ='Data Sheet'!B43 -> 11902 | C5: ='Data Sheet'!C43 -> 11675 | D5: ='Data Sheet'!D43 -> 11965 | E5: ='Data Sheet'!E43 -> 12139 | F5: ='Data Sheet'!F43 -> 11867 | G5: ='Data Sheet'!G43 -> 11572 | H5: ='Data Sheet'!H43 -> 12797 | I5: ='Data Sheet'!I43 -> 12137 | ... K5: ='Data Sheet'!K43 -> 12514
A6: Operating Profit | B6: ='Data Sheet'!B50 -> 3665 | C6: ='Data Sheet'!C50 -> 3535 | D6: ='Data Sheet'!D50 -> 3742 | E6: ='Data Sheet'!E50 -> 3787 | F6: ='Data Sheet'!F50 -> 3689 | G6: ='Data Sheet'!G50 -> 3618 | H6: ='Data Sheet'!H50 -> 3717 | I6: ='Data Sheet'!I50 -> 3782 | ... K6: ='Data Sheet'!K50 -> 3837
A7: Other Income | B7: ='Data Sheet'!B44 -> 184 | C7: ='Data Sheet'!C44 -> 309 | D7: ='Data Sheet'!D44 -> 209 | E7: ='Data Sheet'!E44 -> 203 | F7: ='Data Sheet'!F44 -> 733 | G7: ='Data Sheet'!G44 -> 149 | H7: ='Data Sheet'!H44 -> 74 | I7: ='Data Sheet'!I44 -> 269 | ... K7: ='Data Sheet'!K44 -> 503
A8: Depreciation | B8: ='Data Sheet'!B45 -> 313 | C8: ='Data Sheet'!C45 -> 320 | D8: ='Data Sheet'!D45 -> 329 | E8: ='Data Sheet'!E45 -> 338 | F8: ='Data Sheet'!F45 -> 318 | G8: ='Data Sheet'!G45 -> 318 | H8: ='Data Sheet'!H45 -> 361 | I8: ='Data Sheet'!I45 -> 322 | ... K8: ='Data Sheet'!K45 -> 348
A9: Interest | B9: ='Data Sheet'!B46 -> 91 | C9: ='Data Sheet'!C46 -> 105 | D9: ='Data Sheet'!D46 -> 93 | E9: ='Data Sheet'!E46 -> 110 | F9: ='Data Sheet'!F46 -> 109 | G9: ='Data Sheet'!G46 -> 77 | H9: ='Data Sheet'!H46 -> 127 | I9: ='Data Sheet'!I46 -> 124 | ... K9: ='Data Sheet'!K46 -> 76
A10: Profit before tax | B10: ='Data Sheet'!B47 -> 3445 | C10: ='Data Sheet'!C47 -> 3419 | D10: ='Data Sheet'!D47 -> 3529 | E10: ='Data Sheet'!E47 -> 3542 | F10: ='Data Sheet'!F47 -> 3995 | G10: ='Data Sheet'!G47 -> 3372 | H10: ='Data Sheet'!H47 -> 3303 | I10: ='Data Sheet'!I47 -> 3605 | ... K10: ='Data Sheet'!K47 -> 3916
A11: Tax | B11: ='Data Sheet'!B48 -> 937 | C11: ='Data Sheet'!C48 -> 858 | D11: ='Data Sheet'!D48 -> 917 | E11: ='Data Sheet'!E48 -> 947 | F11: ='Data Sheet'!F48 -> 1006 | G11: ='Data Sheet'!G48 -> 897 | H11: ='Data Sheet'!H48 -> 535 | I11: ='Data Sheet'!I48 -> 911 | ... K11: ='Data Sheet'!K48 -> 922
A12: Net profit | B12: ='Data Sheet'!B49 -> 2509 | C12: ='Data Sheet'!C49 -> 2558 | D12: ='Data Sheet'!D49 -> 2610 | E12: ='Data Sheet'!E49 -> 2591 | F12: ='Data Sheet'!F49 -> 2984 | G12: ='Data Sheet'!G49 -> 2464 | H12: ='Data Sheet'!H49 -> 2756 | I12: ='Data Sheet'!I49 -> 2685 | ... K12: ='Data Sheet'!K49 -> 2992
A14: OPM | B14: =IF(B4>0,B6/B4,"") -> 0.23543393 | C14: =IF(C4>0,C6/C4,"") -> 0.23241289 | D14: =IF(D4>0,D6/D4,"") -> 0.23823773 | E14: =IF(E4>0,E6/E4,"") -> 0.23778727 | F14: =IF(F4>0,F6/F4,"") -> 0.23714322 | G14: =IF(G4>0,G6/G4,"") -> 0.23818302 | H14: =IF(H4>0,H6/H4,"") -> 0.22508175 | I14: =IF(I4>0,I6/I4,"") -> 0.23757774 | ... K14: =IF(K4>0,K6/K4,"") -> 0.23466455

Sheet Balance Sheet
A1: ='Profit & Loss'!A1 -> HINDUSTAN UNILEVER LTD | E1: =UPDATE | J1: SCREENER.IN
A3: Narration | B3: ='Data Sheet'!B56 -> 42825 | C3: ='Data Sheet'!C56 -> 43190 | D3: ='Data Sheet'!D56 -> 43555 | E3: ='Data Sheet'!E56 -> 43921 | F3: ='Data Sheet'!F56 -> 44286 | G3: ='Data Sheet'!G56 -> 44651 | H3: ='Data Sheet'!H56 -> 45016 | I3: ='Data Sheet'!I56 -> 45382 | ... K3: ='Data Sheet'!K56 -> 46112
A4: Equity Share Capital | B4: ='Data Sheet'!B57 -> 216 | C4: ='Data Sheet'!C57 -> 216 | D4: ='Data Sheet'!D57 -> 216 | E4: ='Data Sheet'!E57 -> 216 | F4: ='Data Sheet'!F57 -> 235 | G4: ='Data Sheet'!G57 -> 235 | H4: ='Data Sheet'!H57 -> 235 | I4: ='Data Sheet'!I57 -> 235 | ... K4: ='Data Sheet'!K57 -> 235
A5: Reserves | B5: ='Data Sheet'!B58 -> 6528 | C5: ='Data Sheet'!C58 -> 7065 | D5: ='Data Sheet'!D58 -> 7651 | E5: ='Data Sheet'!E58 -> 8013 | F5: ='Data Sheet'!F58 -> 47439 | G5: ='Data Sheet'!G58 -> 48826 | H5: ='Data Sheet'!H58 -> 50069 | I5: ='Data Sheet'!I58 -> 50983 | ... K5: ='Data Sheet'!K58 -> 48504
A6: Borrowings | B6: ='Data Sheet'!B59 -> 277 | C6: ='Data Sheet'!C59 -> 0 | D6: ='Data Sheet'!D59 -> 99 | E6: ='Data Sheet'!E59 -> 0 | F6: ='Data Sheet'!F59 -> 0 | G6: ='Data Sheet'!G59 -> 1043 | H6: ='Data Sheet'!H59 -> 1219 | I6: ='Data Sheet'!I59 -> 1484 | ... K6: ='Data Sheet'!K59 -> 1478
A7: Other Liabilities | B7: ='Data Sheet'!B60 -> 8685 | C7: ='Data Sheet'!C60 -> 10581 | D7: ='Data Sheet'!D60 -> 10663 | E7: ='Data Sheet'!E60 -> 11924 | F7: ='Data Sheet'!F60 -> 21066 | G7: ='Data Sheet'!G60 -> 20402 | H7: ='Data Sheet'!H60 -> 21554 | I7: ='Data Sheet'!I60 -> 25787 | ... K7: ='Data Sheet'!K60 -> 29535
A8: Total | B8: ='Data Sheet'!B61 -> 15706 | C8: ='Data Sheet'!C61 -> 17862 | D8: ='Data Sheet'!D61 -> 18629 | E8: ='Data Sheet'!E61 -> 20153 | F8: ='Data Sheet'!F61 -> 68740 | G8: ='Data Sheet'!G61 -> 70506 | H8: ='Data Sheet'!H61 -> 73077 | I8: ='Data Sheet'!I61 -> 78489 | ... K8: ='Data Sheet'!K61 -> 79752
A10: Net Block | B10: ='Data Sheet'!B62 -> 4419 | C10: ='Data Sheet'!C62 -> 4528 | D10: ='Data Sheet'!D62 -> 4715 | E10: ='Data Sheet'!E62 -> 5479 | F10: ='Data Sheet'!F62 -> 51443 | G10: ='Data Sheet'!G62 -> 51473 | H10: ='Data Sheet'!H62 -> 52678 | I10: ='Data Sheet'!I62 -> 53744 | ... K10: ='Data Sheet'!K62 -> 57428
A11: Capital Work in Progress | B11: ='Data Sheet'!B63 -> 229 | C11: ='Data Sheet'!C63 -> 461 | D11: ='Data Sheet'!D63 -> 406 | E11: ='Data Sheet'!E63 -> 597 | F11: ='Data Sheet'!F63 -> 745 | G11: ='Data Sheet'!G63 -> 1313 | H11: ='Data Sheet'!H63 -> 1132 | I11: ='Data Sheet'!I63 -> 1025 | ... K11: ='Data Sheet'!K63 -> 880
A12: Investments | B12: ='Data Sheet'!B64 -> 3794 | C12: ='Data Sheet'!C64 -> 2873 | D12: ='Data Sheet'!D64 -> 2716 | E12: ='Data Sheet'!E64 -> 1255 | F12: ='Data Sheet'!F64 -> 2709 | G12: ='Data Sheet'!G64 -> 3521 | H12: ='Data Sheet'!H64 -> 2882 | I12: ='Data Sheet'!I64 -> 4625 | ... K12: ='Data Sheet'!K64 -> 4359
A13: Other Assets | B13: ='Data Sheet'!B65 -> 7264 | C13: ='Data Sheet'!C65 -> 10000 | D13: ='Data Sheet'!D65 -> 10792 | E13: ='Data Sheet'!E65 -> 12822 | F13: ='Data Sheet'!F65 -> 13843 | G13: ='Data Sheet'!G65 -> 14199 | H13: ='Data Sheet'!H65 -> 16385 | I13: ='Data Sheet'!I65 -> 19095 | ... K13: ='Data Sheet'!K65 -> 17085
A14: Total | B14: ='Data Sheet'!B66 -> 15706 | C14: ='Data Sheet'!C66 -> 17862 | D14: ='Data Sheet'!D66 -> 18629 | E14: ='Data Sheet'!E66 -> 20153 | F14: ='Data Sheet'!F66 -> 68740 | G14: ='Data Sheet'!G66 -> 70506 | H14: ='Data Sheet'!H66 -> 73077 | I14: ='Data Sheet'!I66 -> 78489 | ... K14: ='Data Sheet'!K66 -> 79752
A16: Working Capital | B16: =B13-B7 -> -1421 | C16: =C13-C7 -> -581 | D16: =D13-D7 -> 129 | E16: =E13-E7 -> 898 | F16: =F13-F7 -> -7223 | G16: =G13-G7 -> -6203 | H16: =H13-H7 -> -5169 | I16: =I13-I7 -> -6692 | ... K16: =K13-K7 -> -12450
A17: Debtors | B17: ='Data Sheet'!B67 -> 1085 | C17: ='Data Sheet'!C67 -> 1310 | D17: ='Data Sheet'!D67 -> 1816 | E17: ='Data Sheet'!E67 -> 1149 | F17: ='Data Sheet'!F67 -> 1758 | G17: ='Data Sheet'!G67 -> 2236 | H17: ='Data Sheet'!H67 -> 3079 | I17: ='Data Sheet'!I67 -> 2997 | ... K17: ='Data Sheet'!K67 -> 3379
A18: Inventory | B18: ='Data Sheet'!B68 -> 2541 | C18: ='Data Sheet'!C68 -> 2513 | D18: ='Data Sheet'!D68 -> 2574 | E18: ='Data Sheet'!E68 -> 2767 | F18: ='Data Sheet'!F68 -> 3579 | G18: ='Data Sheet'!G68 -> 4096 | H18: ='Data Sheet'!H68 -> 4251 | I18: ='Data Sheet'!I68 -> 4022 | ... K18: ='Data Sheet'!K68 -> 4789
A20: Debtor Days | B20: =IF('Profit & Loss'!B4>0,'Balance Sheet'!B17/('Profit & Loss'!B4/365),0) -> 11.942133 | C20: =IF('Profit & Loss'!C4>0,'Balance Sheet'!C17/('Profit & Loss'!C4/365),0) -> 13.451962 | D20: =IF('Profit & Loss'!D4>0,'Balance Sheet'!D17/('Profit & Loss'!D4/365),0) -> 16.861867 | E20: =IF('Profit & Loss'!E4>0,'Balance Sheet'!E17/('Profit & Loss'!E4/365),0) -> 10.541814 | F20: =IF('Profit & Loss'!F4>0,'Balance Sheet'!F17/('Profit & Loss'!F4/365),0) -> 13.644425 | G20: =IF('Profit & Loss'!G4>0,'Balance Sheet'!G17/('Profit & Loss'!G4/365),0) -> 15.56153 | H20: =IF('Profit & Loss'!H4>0,'Balance Sheet'!H17/('Profit & Loss'!H4/365),0) -> 18.551255 | I20: =IF('Profit & Loss'!I4>0,'Balance Sheet'!I17/('Profit & Loss'!I4/365),0) -> 17.673275 | ... K20: =IF('Profit & Loss'!K4>0,'Balance Sheet'!K17/('Profit & Loss'!K4/365),0) -> 19.130964
A21: Inventory Turnover | B21: =IF('Balance Sheet'!B18>0,'Profit & Loss'!B4/'Balance Sheet'!B18,0) -> 13.050767 | C21: =IF('Balance Sheet'!C18>0,'Profit & Loss'!C4/'Balance Sheet'!C18,0) -> 14.144449 | D21: =IF('Balance Sheet'!D18>0,'Profit & Loss'!D4/'Balance Sheet'!D18,0) -> 15.27195 | E21: =IF('Balance Sheet'!E18>0,'Profit & Loss'!E4/'Balance Sheet'!E18,0) -> 14.377665 | F21: =IF('Balance Sheet'!F18>0,'Profit & Loss'!F4/'Balance Sheet'!F18,0) -> 13.139983 | G21: =IF('Balance Sheet'!G18>0,'Profit & Loss'!G4/'Balance Sheet'!G18,0) -> 12.804199 | H21: =IF('Balance Sheet'!H18>0,'Profit & Loss'!H4/'Balance Sheet'!H18,0) -> 14.250765 | I21: =IF('Balance Sheet'!I18>0,'Profit & Loss'!I4/'Balance Sheet'!I18,0) -> 15.389359 | ... K21: =IF('Balance Sheet'!K18>0,'Profit & Loss'!K4/'Balance Sheet'!K18,0) -> 13.461683
A23: Return on Equity | B23: =IF(SUM('Balance Sheet'!B4:B5)>0,'Profit & Loss'!B12/SUM('Balance Sheet'!B4:B5),"") -> 0.66370107 | C23: =IF(SUM('Balance Sheet'!C4:C5)>0,'Profit & Loss'!C12/SUM('Balance Sheet'!C4:C5),"") -> 0.71611042 | D23: =IF(SUM('Balance Sheet'!D4:D5)>0,'Profit & Loss'!D12/SUM('Balance Sheet'!D4:D5),"") -> 0.76954366 | E23: =IF(SUM('Balance Sheet'!E4:E5)>0,'Profit & Loss'!E12/SUM('Balance Sheet'!E4:E5),"") -> 0.82002673 | F23: =IF(SUM('Balance Sheet'!F4:F5)>0,'Profit & Loss'!F12/SUM('Balance Sheet'!F4:F5),"") -> 0.16770147 | G23: =IF(SUM('Balance Sheet'!G4:G5)>0,'Profit & Loss'!G12/SUM('Balance Sheet'!G4:G5),"") -> 0.18097878 | H23: =IF(SUM('Balance Sheet'!H4:H5)>0,'Profit & Loss'!H12/SUM('Balance Sheet'!H4:H5),"") -> 0.20117684 | I23: =IF(SUM('Balance Sheet'!I4:I5)>0,'Profit & Loss'!I12/SUM('Balance Sheet'!I4:I5),"") -> 0.20065211 | ... K23: =IF(SUM('Balance Sheet'!K4:K5)>0,'Profit & Loss'!K12/SUM('Balance Sheet'!K4:K5),"") -> 0.30858245
A24: Return on Capital Emp | C24: =IF((B4+B5+B6+C4+C5+C6)>0,('Profit & Loss'!C10+'Profit & Loss'!C9)*2/(B4+B5+B6+C4+C5+C6),"") -> 1.0253111 | D24: =IF((C4+C5+C6+D4+D5+D6)>0,('Profit & Loss'!D10+'Profit & Loss'!D9)*2/(C4+C5+C6+D4+D5+D6),"") -> 1.1329442 | E24: =IF((D4+D5+D6+E4+E5+E6)>0,('Profit & Loss'!E10+'Profit & Loss'!E9)*2/(D4+D5+D6+E4+E5+E6),"") -> 1.1464032 | F24: =IF((E4+E5+E6+F4+F5+F6)>0,('Profit & Loss'!F10+'Profit & Loss'!F9)*2/(E4+E5+E6+F4+F5+F6),"") -> 0.38359301 | G24: =IF((F4+F5+F6+G4+G5+G6)>0,('Profit & Loss'!G10+'Profit & Loss'!G9)*2/(F4+F5+F6+G4+G5+G6),"") -> 0.24514717 | H24: =IF((G4+G5+G6+H4+H5+H6)>0,('Profit & Loss'!H10+'Profit & Loss'!H9)*2/(G4+G5+G6+H4+H5+H6),"") -> 0.26485088 | I24: =IF((H4+H5+H6+I4+I5+I6)>0,('Profit & Loss'!I10+'Profit & Loss'!I9)*2/(H4+H5+H6+I4+I5+I6),"") -> 0.27363876 | J24: =IF((I4+I5+I6+J4+J5+J6)>0,('Profit & Loss'!J10+'Profit & Loss'!J9)*2/(I4+I5+I6+J4+J5+J6),"") -> 0.28548847 | K24: =IF((J4+J5+J6+K4+K5+K6)>0,('Profit & Loss'!K10+'Profit & Loss'!K9)*2/(J4+J5+J6+K4+K5+K6),"") -> 0.36791847

Sheet Cash Flow
A1: ='Balance Sheet'!A1 -> HINDUSTAN UNILEVER LTD | E1: =UPDATE | J1: SCREENER.IN
A3: Narration | B3: ='Data Sheet'!B81 -> 42825 | C3: ='Data Sheet'!C81 -> 43190 | D3: ='Data Sheet'!D81 -> 43555 | E3: ='Data Sheet'!E81 -> 43921 | F3: ='Data Sheet'!F81 -> 44286 | G3: ='Data Sheet'!G81 -> 44651 | H3: ='Data Sheet'!H81 -> 45016 | I3: ='Data Sheet'!I81 -> 45382 | ... K3: ='Data Sheet'!K81 -> 46112
A4: Cash from Operating Activity | B4: ='Data Sheet'!B113 -> 5185 | C4: ='Data Sheet'!C113 -> 6059 | D4: ='Data Sheet'!D113 -> 5800 | E4: ='Data Sheet'!E113 -> 7623 | F4: ='Data Sheet'!F113 -> 9163 | G4: ='Data Sheet'!G113 -> 9048 | H4: ='Data Sheet'!H113 -> 9991 | I4: ='Data Sheet'!I113 -> 15469 | ... K4: ='Data Sheet'!K113 -> 10999
A5: Cash from Investing Activity | B5: ='Data Sheet'!B114 -> -1173 | C5: ='Data Sheet'!C114 -> -1063 | D5: ='Data Sheet'!D114 -> -438 | E5: ='Data Sheet'!E114 -> 1791 | F5: ='Data Sheet'!F114 -> -1228 | G5: ='Data Sheet'!G114 -> -1728 | H5: ='Data Sheet'!H114 -> -1484 | I5: ='Data Sheet'!I114 -> -5324 | ... K5: ='Data Sheet'!K114 -> -3684
A6: Cash from Financing Activity | B6: ='Data Sheet'!B115 -> -4214 | C6: ='Data Sheet'!C115 -> -4975 | D6: ='Data Sheet'!D115 -> -5390 | E6: ='Data Sheet'!E115 -> -6819 | F6: ='Data Sheet'!F115 -> -9309 | G6: ='Data Sheet'!G115 -> -8015 | H6: ='Data Sheet'!H115 -> -8953 | I6: ='Data Sheet'!I115 -> -10034 | ... K6: ='Data Sheet'!K115 -> -10810
A7: Net Cash Flow | B7: ='Data Sheet'!B116 -> -202 | C7: ='Data Sheet'!C116 -> 21 | D7: ='Data Sheet'!D116 -> -28 | E7: ='Data Sheet'!E116 -> 2595 | F7: ='Data Sheet'!F116 -> -1374 | G7: ='Data Sheet'!G116 -> -695 | H7: ='Data Sheet'!H116 -> -446 | I7: ='Data Sheet'!I116 -> 111 | ... K7: ='Data Sheet'!K116 -> -3495

Sheet Customization
A1: How to use it?
A3: You can customize this workbook as you want.
B4: You can add custom formating, add conditional formating, add your own formulas… do ANYTHING.
B5: Please don't edit the "Data Sheet" only.
A7: After customization, you can upload this back on Screener.
B8: Upload on: | C8: https://www.screener.in/excel/
A10: Download your customized workbooks now onwards.
B11: Now whenever you will "Export to excel" from Screener, it will export your customized file.
A14: TESTING:
B15: This is a testing feature currently.
B16: You can report any formula errors on the worksheet at: support@screener.in

Sheet Data Sheet
A1: COMPANY NAME | B1: HINDUSTAN UNILEVER LTD | E1: =IF(B2<>B3,"A NEW VERSION OF THE WORKSHEET IS AVAILABLE","")
A2: LATEST VERSION | B2: 2.1 | E2: PLEASE DO NOT MAKE ANY CHANGES TO THIS SHEET
A3: CURRENT VERSION | B3: 2.1
A5: META
A6: Number of shares | B6: =IF(B9>0,B9/B8,0) -> 235.12985
A7: Face Value | B7: 1
A8: Current Price | B8: 2197.45
A9: Market Capitalization | B9: 516686.09
A15: PROFIT & LOSS
A16: Report Date | B16: 42825 | C16: 43190 | D16: 43555 | E16: 43921 | F16: 44286 | G16: 44651 | H16: 45016 | I16: 45382 | J16: 45747 | K16: 46112
A17: Sales | B17: 33162 | C17: 35545 | D17: 39310 | E17: 39783 | F17: 47028 | G17: 52446 | H17: 60580 | I17: 61896 | J17: 63121 | K17: 64468
A18: Raw Material Cost | B18: 13606 | C18: 14233 | D18: 15845 | E18: 15697 | F18: 20141 | G18: 22871 | H18: 28427 | I18: 26822 | J18: 27344 | K18: 32094
A19: Change in Inventory | B19: -144 | C19: 72 | D19: -12 | E19: 108 | F19: 405 | G19: 22 | H19: 75 | I19: 11 | J19: 153 | K19: 429
A20: Power and Fuel | B20: 295 | C20: 295 | D20: 308 | E20: 299 | F20: 339 | G20: 318 | H20: 384 | I20: 446 | J20: 427
A21: Other Mfr. Exp | B21: 2887 | C21: 2998 | D21: 3041 | E21: 2906 | F21: 2868 | G21: 3354 | H21: 3791 | I21: 3385 | J21: 3834
A22: Employee Cost | B22: 1743 | C22: 1860 | D22: 1875 | E22: 1820 | F22: 2358 | G22: 2545 | H22: 2854 | I22: 3009 | J22: 3077 | K22: 3175
A23: Selling and admin | B23: 6689 | C23: 7252 | D23: 7796 | E23: 7620 | F23: 7906 | G23: 8164 | H23: 8785 | I23: 10780 | J23: 10693 | K23: 6261
A24: Other Expenses | B24: 1470 | C24: 1480 | D24: 1553 | E24: 1688 | F24: 2195 | G24: 2359 | H24: 2267 | I24: 2806 | J24: 3056 | K24: 8328
A25: Other Income | B25: 606 | C25: 353 | D25: 322 | E25: 424 | F25: 170 | G25: 219 | H25: 448 | I25: 817 | J25: 1322 | K25: 4923
A26: Depreciation | B26: 432 | C26: 520 | D26: 565 | E26: 1002 | F26: 1074 | G26: 1091 | H26: 1137 | I26: 1216 | J26: 1355 | K26: 1333
A27: Interest | B27: 35 | C27: 26 | D27: 33 | E27: 118 | F27: 117 | G27: 106 | H27: 114 | I27: 334 | J27: 395 | K27: 410
A28: Profit before tax | B28: 6467 | C28: 7306 | D28: 8604 | E28: 9165 | F28: 10605 | G28: 11879 | H28: 13344 | I28: 13926 | J28: 14415 | K28: 18219
A29: Tax | B29: 1977 | C29: 2079 | D29: 2544 | E29: 2409 | F29: 2606 | G29: 2987 | H29: 3201 | I29: 3644 | J29: 3744 | K29: 3160
A30: Net profit | B30: 4476 | C30: 5214 | D30: 6054 | E30: 6748 | F30: 7995 | G30: 8879 | H30: 10120 | I30: 10277 | J30: 10649 | K30: 15040
A31: Dividend Amount | B31: 3672 | C31: 4320 | D31: 4752 | E31: 5400 | F31: 9517.5 | G31: 7990 | H31: 9165 | I31: 9870 | J31: 12455 | K31: 9635
A32: EBITDA | B32: =B28+B27+B26 -> 6934 | C32: =C28+C27+C26 -> 7852 | D32: =D28+D27+D26 -> 9202 | E32: =E28+E27+E26 -> 10285 | F32: =F28+F27+F26 -> 11796 | G32: =G28+G27+G26 -> 13076 | H32: =H28+H27+H26 -> 14595 | I32: =I28+I27+I26 -> 15476 | ... K32: =K28+K27+K26 -> 19962
A33: EBIT | B33: =B28+B27 -> 6502 | C33: =C28+C27 -> 7332 | D33: =D28+D27 -> 8637 | E33: =E28+E27 -> 9283 | F33: =F28+F27 -> 10722 | G33: =G28+G27 -> 11985 | H33: =H28+H27 -> 13458 | I33: =I28+I27 -> 14260 | ... K33: =K28+K27 -> 18629
A40: Quarters
A41: Report Date | B41: 45291 | C41: 45382 | D41: 45473 | E41: 45565 | F41: 45657 | G41: 45747 | H41: 45838 | I41: 45930 | J41: 46022 | K41: 46112
A42: Sales | B42: 15567 | C42: 15210 | D42: 15707 | E42: 15926 | F42: 15556 | G42: 15190 | H42: 16514 | I42: 15919 | J42: 16441 | K42: 16351
A43: Expenses | B43: 11902 | C43: 11675 | D43: 11965 | E43: 12139 | F43: 11867 | G43: 11572 | H43: 12797 | I43: 12137 | J43: 12660 | K43: 12514
A44: Other Income | B44: 184 | C44: 309 | D44: 209 | E44: 203 | F44: 733 | G44: 149 | H44: 74 | I44: 269 | J44: 4048 | K44: 503
A45: Depreciation | B45: 313 | C45: 320 | D45: 329 | E45: 338 | F45: 318 | G45: 318 | H45: 361 | I45: 322 | J45: 337 | K45: 348
A46: Interest | B46: 91 | C46: 105 | D46: 93 | E46: 110 | F46: 109 | G46: 77 | H46: 127 | I46: 124 | J46: 88 | K46: 76
A47: Profit before tax | B47: 3445 | C47: 3419 | D47: 3529 | E47: 3542 | F47: 3995 | G47: 3372 | H47: 3303 | I47: 3605 | J47: 7404 | K47: 3916
A48: Tax | B48: 937 | C48: 858 | D48: 917 | E48: 947 | F48: 1006 | G48: 897 | H48: 535 | I48: 911 | J48: 801 | K48: 922
A49: Net profit | B49: 2509 | C49: 2558 | D49: 2610 | E49: 2591 | F49: 2984 | G49: 2464 | H49: 2756 | I49: 2685 | J49: 6607 | K49: 2992
A50: Operating Profit | B50: 3665 | C50: 3535 | D50: 3742 | E50: 3787 | F50: 3689 | G50: 3618 | H50: 3717 | I50: 3782 | J50: 3781 | K50: 3837
A55: BALANCE SHEET
A56: Report Date | B56: 42825 | C56: 43190 | D56: 43555 | E56: 43921 | F56: 44286 | G56: 44651 | H56: 45016 | I56: 45382 | J56: 45747 | K56: 46112
...

Sheet Historical FS
B2: ="Historical Financial Statements for "&'Data Sheet'!B1 -> Historical Financial Statements for HINDUSTAN UNILEVER LTD
B3: Year | C3: ='Data Sheet'!B16 -> 42825 | D3: ='Data Sheet'!C16 -> 43190 | E3: ='Data Sheet'!D16 -> 43555 | F3: ='Data Sheet'!E16 -> 43921 | G3: ='Data Sheet'!F16 -> 44286 | H3: ='Data Sheet'!G16 -> 44651 | I3: ='Data Sheet'!H16 -> 45016 | J3: ='Data Sheet'!I16 -> 45382 | ... L3: ='Data Sheet'!K16 -> 46112 | M3: ='Data Sheet'!K56+365 -> 46477 | N3: =M3+365 -> 46842 | O3: =N3+365 -> 47207 | P3: =O3+365 -> 47572
A5: # | B5: Income Statement | R5: CAGR
B6: ='Data Sheet'!A17 -> Sales | C6: ='Data Sheet'!B17 -> 33162 | D6: ='Data Sheet'!C17 -> 35545 | E6: ='Data Sheet'!D17 -> 39310 | F6: ='Data Sheet'!E17 -> 39783 | G6: ='Data Sheet'!F17 -> 47028 | H6: ='Data Sheet'!G17 -> 52446 | I6: ='Data Sheet'!H17 -> 60580 | ... L6: ='Data Sheet'!K17 -> 64468 | M6: =FORECAST(M$3,C6:L6,C$3:L$3) -> 71580.023 | N6: =FORECAST(N$3,D6:M6,D$3:M$3) -> 75897.69 | O6: =FORECAST(O$3,E6:N6,E$3:N$3) -> 80018.286 | P6: =FORECAST(P$3,F6:O6,F$3:O$3) -> 84102.444 | R6: =((L6/C6)^(1/10))-1 -> 0.068735777
B7: Sales Growth | C7: - | D7: =D6/C6-1 -> 0.071859357 | E7: =E6/D6-1 -> 0.10592207 | F7: =F6/E6-1 -> 0.012032562 | G7: =G6/F6-1 -> 0.18211296 | H7: =H6/G6-1 -> 0.11520796 | I7: =I6/H6-1 -> 0.15509286 | J7: =J6/I6-1 -> 0.021723341 | K7: =K6/J6-1 -> 0.019791263 | ... P7: =P6/O6-1 -> 0.051040306
B9: COGS | C9: =SUM('Data Sheet'!B18,'Data Sheet'!B20:B22)-(1*'Data Sheet'!B19) -> 18675 | D9: =SUM('Data Sheet'!C18,'Data Sheet'!C20:C22)-(1*'Data Sheet'!C19) -> 19314 | E9: =SUM('Data Sheet'!D18,'Data Sheet'!D20:D22)-(1*'Data Sheet'!D19) -> 21081 | F9: =SUM('Data Sheet'!E18,'Data Sheet'!E20:E22)-(1*'Data Sheet'!E19) -> 20614 | G9: =SUM('Data Sheet'!F18,'Data Sheet'!F20:F22)-(1*'Data Sheet'!F19) -> 25301 | H9: =SUM('Data Sheet'!G18,'Data Sheet'!G20:G22)-(1*'Data Sheet'!G19) -> 29066 | I9: =SUM('Data Sheet'!H18,'Data Sheet'!H20:H22)-(1*'Data Sheet'!H19) -> 35381 | J9: =SUM('Data Sheet'!I18,'Data Sheet'!I20:I22)-(1*'Data Sheet'!I19) -> 33651 | ... L9: =SUM('Data Sheet'!K18,'Data Sheet'!K20:K22)-(1*'Data Sheet'!K19) -> 34840 | M9: =FORECAST(M$3,C9:L9,C$3:L$3) -> 39339.249 | N9: =FORECAST(N$3,D9:M9,D$3:M$3) -> 41890.518 | O9: =FORECAST(O$3,E9:N9,E$3:N$3) -> 44256.027 | P9: =FORECAST(P$3,F9:O9,F$3:O$3) -> 46534.688
B11: Gross Profit | C11: =C6-C9 -> 14487 | D11: =D6-D9 -> 16231 | E11: =E6-E9 -> 18229 | F11: =F6-F9 -> 19169 | G11: =G6-G9 -> 21727 | H11: =H6-H9 -> 23380 | I11: =I6-I9 -> 25199 | J11: =J6-J9 -> 28245 | ... P11: =P6-P9 -> 37567.756
B12: Gross Profit Margins | C12: =C11/C6 -> 0.43685544 | D12: =D11/D6 -> 0.45663244 | E12: =E11/E6 -> 0.46372424 | F12: =F11/F6 -> 0.48183898 | G12: =G11/G6 -> 0.46200136 | H12: =H11/H6 -> 0.44579186 | I12: =I11/I6 -> 0.41596236 | J12: =J11/J6 -> 0.45632997 | ... P12: =P11/P6 -> 0.44669042
B14: Selling & General Expenses | C14: =SUM('Data Sheet'!B23:B24) -> 8159 | D14: =SUM('Data Sheet'!C23:C24) -> 8732 | E14: =SUM('Data Sheet'!D23:D24) -> 9349 | F14: =SUM('Data Sheet'!E23:E24) -> 9308 | G14: =SUM('Data Sheet'!F23:F24) -> 10101 | H14: =SUM('Data Sheet'!G23:G24) -> 10523 | I14: =SUM('Data Sheet'!H23:H24) -> 11052 | J14: =SUM('Data Sheet'!I23:I24) -> 13586 | ... L14: =SUM('Data Sheet'!K23:K24) -> 14589 | M14: =FORECAST(M$3,C14:L14,C$3:L$3) -> 14908.35 | N14: =FORECAST(N$3,D14:M14,D$3:M$3) -> 15770.563 | O14: =FORECAST(O$3,E14:N14,E$3:N$3) -> 16680.804 | P14: =FORECAST(P$3,F14:O14,F$3:O$3) -> 17650.803
B16: EBITDA | C16: =C11-C14 -> 6328 | D16: =D11-D14 -> 7499 | E16: =E11-E14 -> 8880 | F16: =F11-F14 -> 9861 | G16: =G11-G14 -> 11626 | H16: =H11-H14 -> 12857 | I16: =I11-I14 -> 14147 | J16: =J11-J14 -> 14659 | ... P16: =P11-P14 -> 19916.953
B17: EBITDA Margins | C17: =C16/C6 -> 0.19082082 | D17: =D16/D6 -> 0.21097201 | E17: =E16/E6 -> 0.22589672 | F17: =F16/F6 -> 0.24786969 | G17: =G16/G6 -> 0.24721443 | H17: =H16/H6 -> 0.24514739 | I17: =I16/I6 -> 0.23352592 | J17: =J16/J6 -> 0.23683275 | ... P17: =P16/P6 -> 0.23681777
B19: D&A | C19: ='Data Sheet'!B26 -> 432 | D19: ='Data Sheet'!C26 -> 520 | E19: ='Data Sheet'!D26 -> 565 | F19: ='Data Sheet'!E26 -> 1002 | G19: ='Data Sheet'!F26 -> 1074 | H19: ='Data Sheet'!G26 -> 1091 | I19: ='Data Sheet'!H26 -> 1137 | J19: ='Data Sheet'!I26 -> 1216 | ... L19: ='Data Sheet'!K26 -> 1333 | M19: =FORECAST(M$3,C19:L19,C$3:L$3) -> 1560.1091 | N19: =FORECAST(N$3,D19:M19,D$3:M$3) -> 1650.9876 | O19: =FORECAST(O$3,E19:N19,E$3:N$3) -> 1726.5137 | P19: =FORECAST(P$3,F19:O19,F$3:O$3) -> 1768.8664
B21: EBIT | C21: =C16-C19 -> 5896 | D21: =D16-D19 -> 6979 | E21: =E16-E19 -> 8315 | F21: =F16-F19 -> 8859 | G21: =G16-G19 -> 10552 | H21: =H16-H19 -> 11766 | I21: =I16-I19 -> 13010 | J21: =J16-J19 -> 13443 | ... P21: =P16-P19 -> 18148.087
B22: EBIT Margins | C22: =C21/C6 -> 0.17779386 | D22: =D21/D6 -> 0.19634266 | E22: =E21/E6 -> 0.21152379 | F22: =F21/F6 -> 0.22268306 | G22: =G21/G6 -> 0.22437697 | H22: =H21/H6 -> 0.22434504 | I22: =I21/I6 -> 0.21475735 | J22: =J21/J6 -> 0.21718689 | ... P22: =P21/P6 -> 0.21578549
B24: Interest | C24: ='Data Sheet'!B27 -> 35 | D24: ='Data Sheet'!C27 -> 26 | E24: ='Data Sheet'!D27 -> 33 | F24: ='Data Sheet'!E27 -> 118 | G24: ='Data Sheet'!F27 -> 117 | H24: ='Data Sheet'!G27 -> 106 | I24: ='Data Sheet'!H27 -> 114 | J24: ='Data Sheet'!I27 -> 334 | ... L24: ='Data Sheet'!K27 -> 410 | M24: =FORECAST(M$3,C24:L24,C$3:L$3) -> 416.76851 | N24: =FORECAST(N$3,D24:M24,D$3:M$3) -> 480.25104 | O24: =FORECAST(O$3,E24:N24,E$3:N$3) -> 541.29814 | P24: =FORECAST(P$3,F24:O24,F$3:O$3) -> 598.36985
B26: EBT | C26: =C21-C24 -> 5861 | D26: =D21-D24 -> 6953 | E26: =E21-E24 -> 8282 | F26: =F21-F24 -> 8741 | G26: =G21-G24 -> 10435 | H26: =H21-H24 -> 11660 | I26: =I21-I24 -> 12896 | J26: =J21-J24 -> 13109 | ... P26: =P21-P24 -> 17549.717
B27: EBT Margins | C27: =C26/C6 -> 0.17673844 | D27: =D26/D6 -> 0.1956112 | E27: =E26/E6 -> 0.2106843 | F27: =F26/F6 -> 0.21971696 | G27: =G26/G6 -> 0.22188909 | H27: =H26/H6 -> 0.22232391 | I27: =I26/I6 -> 0.21287554 | J27: =J26/J6 -> 0.21179075 | ... P27: =P26/P6 -> 0.20867071
B29: Tax | C29: ='Data Sheet'!B29 -> 1977 | D29: ='Data Sheet'!C29 -> 2079 | E29: ='Data Sheet'!D29 -> 2544 | F29: ='Data Sheet'!E29 -> 2409 | G29: ='Data Sheet'!F29 -> 2606 | H29: ='Data Sheet'!G29 -> 2987 | I29: ='Data Sheet'!H29 -> 3201 | J29: ='Data Sheet'!I29 -> 3644 | ... L29: ='Data Sheet'!K29 -> 3160 | M29: =FORECAST(M$3,C29:L29,C$3:L$3) -> 3853.5412 | N29: =FORECAST(N$3,D29:M29,D$3:M$3) -> 4032.0264 | O29: =FORECAST(O$3,E29:N29,E$3:N$3) -> 4184.0732 | P29: =FORECAST(P$3,F29:O29,F$3:O$3) -> 4390.804
B31: Net Profit | C31: =C26-C29 -> 3884 | D31: =D26-D29 -> 4874 | E31: =E26-E29 -> 5738 | F31: =F26-F29 -> 6332 | G31: =G26-G29 -> 7829 | H31: =H26-H29 -> 8673 | I31: =I26-I29 -> 9695 | J31: =J26-J29 -> 9465 | ... P31: =P26-P29 -> 13158.913
B32: Net Profit Margins | C32: =C31/C6 -> 0.11712201 | D32: =D31/D6 -> 0.13712196 | E32: =E31/E6 -> 0.14596795 | F32: =F31/F6 -> 0.15916346 | G32: =G31/G6 -> 0.16647529 | H32: =H31/H6 -> 0.16537009 | I32: =I31/I6 -> 0.16003632 | J32: =J31/J6 -> 0.1529178 | ... P32: =P31/P6 -> 0.15646291
A34: # | B34: Balance Sheet
B35: Equity Share Capital | C35: ='Data Sheet'!B57 -> 216 | D35: ='Data Sheet'!C57 -> 216 | E35: ='Data Sheet'!D57 -> 216 | F35: ='Data Sheet'!E57 -> 216 | G35: ='Data Sheet'!F57 -> 235 | H35: ='Data Sheet'!G57 -> 235 | I35: ='Data Sheet'!H57 -> 235 | J35: ='Data Sheet'!I57 -> 235 | ... L35: ='Data Sheet'!K57 -> 235 | M35: =FORECAST(M$3,C35:L35,C$3:L$3) -> 242.59678 | N35: =FORECAST(N$3,D35:M35,D$3:M$3) -> 245.63436 | O35: =FORECAST(O$3,E35:N35,E$3:N$3) -> 248.11505 | P35: =FORECAST(P$3,F35:O35,F$3:O$3) -> 249.61299
B36: Reserves | C36: ='Data Sheet'!B58 -> 6528 | D36: ='Data Sheet'!C58 -> 7065 | E36: ='Data Sheet'!D58 -> 7651 | F36: ='Data Sheet'!E58 -> 8013 | G36: ='Data Sheet'!F58 -> 47439 | H36: ='Data Sheet'!G58 -> 48826 | I36: ='Data Sheet'!H58 -> 50069 | J36: ='Data Sheet'!I58 -> 50983 | ... L36: ='Data Sheet'!K58 -> 48504 | M36: =FORECAST(M$3,C36:L36,C$3:L$3) -> 66307.82 | N36: =FORECAST(N$3,D36:M36,D$3:M$3) -> 72952.943 | O36: =FORECAST(O$3,E36:N36,E$3:N$3) -> 78416.614 | P36: =FORECAST(P$3,F36:O36,F$3:O$3) -> 81830.834
B37: Borrowings | C37: ='Data Sheet'!B59 -> 277 | D37: ='Data Sheet'!C59 -> 0 | E37: ='Data Sheet'!D59 -> 99 | F37: ='Data Sheet'!E59 -> 0 | G37: ='Data Sheet'!F59 -> 0 | H37: ='Data Sheet'!G59 -> 1043 | I37: ='Data Sheet'!H59 -> 1219 | J37: ='Data Sheet'!I59 -> 1484 | ... L37: ='Data Sheet'!K59 -> 1478 | M37: =FORECAST(M$3,C37:L37,C$3:L$3) -> 1856.8915 | N37: =FORECAST(N$3,D37:M37,D$3:M$3) -> 2190.1813 | O37: =FORECAST(O$3,E37:N37,E$3:N$3) -> 2477.7187 | P37: =FORECAST(P$3,F37:O37,F$3:O$3) -> 2760.7683
B38: Other Liabilities | C38: ='Data Sheet'!B60-C39 -> 2499 | D38: ='Data Sheet'!C60-D39 -> 3411 | E38: ='Data Sheet'!D60-E39 -> 3457 | F38: ='Data Sheet'!E60-F39 -> 4389 | G38: ='Data Sheet'!F60-G39 -> 12264 | H38: ='Data Sheet'!G60-H39 -> 11334 | I38: ='Data Sheet'!H60-I39 -> 11980 | J38: ='Data Sheet'!I60-J39 -> 15301 | ... L38: ='Data Sheet'!K60-L39 -> 16210 | M38: =FORECAST(M$3,C38:L38,C$3:L$3) -> 19934.85 | N38: =FORECAST(N$3,D38:M38,D$3:M$3) -> 22018.206 | O38: =FORECAST(O$3,E38:N38,E$3:N$3) -> 24016.48 | P38: =FORECAST(P$3,F38:O38,F$3:O$3) -> 25586.474
B39: Trade Payables | C39: 6186 | D39: 7170 | E39: 7206 | F39: 7535 | G39: 8802 | H39: 9068 | I39: 9574 | J39: 10486 | K39: 11315 | L39: 13325 | M39: =FORECAST(M$3,C39:L39,C$3:L$3) -> 12934.192 | N39: =FORECAST(N$3,D39:M39,D$3:M$3) -> 13712.711 | O39: =FORECAST(O$3,E39:N39,E$3:N$3) -> 14615.416 | P39: =FORECAST(P$3,F39:O39,F$3:O$3) -> 15452.955
B41: Total Liabilities | C41: =SUM(C35:C39) -> 15706 | D41: =SUM(D35:D39) -> 17862 | E41: =SUM(E35:E39) -> 18629 | F41: =SUM(F35:F39) -> 20153 | G41: =SUM(G35:G39) -> 68740 | H41: =SUM(H35:H39) -> 70506 | I41: =SUM(I35:I39) -> 73077 | J41: =SUM(J35:J39) -> 78489 | ... P41: =SUM(P35:P39) -> 125880.64
B43: Net Block | C43: ='Data Sheet'!B62 -> 4419 | D43: ='Data Sheet'!C62 -> 4528 | E43: ='Data Sheet'!D62 -> 4715 | F43: ='Data Sheet'!E62 -> 5479 | G43: ='Data Sheet'!F62 -> 51443 | H43: ='Data Sheet'!G62 -> 51473 | I43: ='Data Sheet'!H62 -> 52678 | J43: ='Data Sheet'!I62 -> 53744 | ... L43: ='Data Sheet'!K62 -> 57428 | M43: =FORECAST(M$3,C43:L43,C$3:L$3) -> 74432.432 | N43: =FORECAST(N$3,D43:M43,D$3:M$3) -> 82697.901 | O43: =FORECAST(O$3,E43:N43,E$3:N$3) -> 89634.283 | P43: =FORECAST(P$3,F43:O43,F$3:O$3) -> 94185.566
B44: Capital Work in Progress | C44: ='Data Sheet'!B63 -> 229 | D44: ='Data Sheet'!C63 -> 461 | E44: ='Data Sheet'!D63 -> 406 | F44: ='Data Sheet'!E63 -> 597 | G44: ='Data Sheet'!F63 -> 745 | H44: ='Data Sheet'!G63 -> 1313 | I44: ='Data Sheet'!H63 -> 1132 | J44: ='Data Sheet'!I63 -> 1025 | ... L44: ='Data Sheet'!K63 -> 880 | M44: =FORECAST(M$3,C44:L44,C$3:L$3) -> 1278.3516 | N44: =FORECAST(N$3,D44:M44,D$3:M$3) -> 1330.9431 | O44: =FORECAST(O$3,E44:N44,E$3:N$3) -> 1396.4998 | P44: =FORECAST(P$3,F44:O44,F$3:O$3) -> 1415.6257
B45: Investments | C45: ='Data Sheet'!B64 -> 3794 | D45: ='Data Sheet'!C64 -> 2873 | E45: ='Data Sheet'!D64 -> 2716 | F45: ='Data Sheet'!E64 -> 1255 | G45: ='Data Sheet'!F64 -> 2709 | H45: ='Data Sheet'!G64 -> 3521 | I45: ='Data Sheet'!H64 -> 2882 | J45: ='Data Sheet'!I64 -> 4625 | ... L45: ='Data Sheet'!K64 -> 4359 | M45: =FORECAST(M$3,C45:L45,C$3:L$3) -> 4150.2863 | N45: =FORECAST(N$3,D45:M45,D$3:M$3) -> 4652.3198 | O45: =FORECAST(O$3,E45:N45,E$3:N$3) -> 5085.9946 | P45: =FORECAST(P$3,F45:O45,F$3:O$3) -> 5532.8346
B46: Other Assets | C46: ='Data Sheet'!B65-SUM('Data Sheet'!B67:B69) -> 1810 | D46: ='Data Sheet'!C65-SUM('Data Sheet'!C67:C69) -> 2692 | E46: ='Data Sheet'!D65-SUM('Data Sheet'!D67:D69) -> 2645 | F46: ='Data Sheet'!E65-SUM('Data Sheet'!E67:E69) -> 3793 | G46: ='Data Sheet'!F65-SUM('Data Sheet'!F67:F69) -> 4035 | H46: ='Data Sheet'!G65-SUM('Data Sheet'!G67:G69) -> 4021 | I46: ='Data Sheet'!H65-SUM('Data Sheet'!H67:H69) -> 4377 | J46: ='Data Sheet'!I65-SUM('Data Sheet'!I67:I69) -> 4517 | ... L46: ='Data Sheet'!K65-SUM('Data Sheet'!K67:K69) -> 5669 | M46: =FORECAST(M$3,C46:L46,C$3:L$3) -> 5895.3513 | N46: =FORECAST(N$3,D46:M46,D$3:M$3) -> 6170.7334 | O46: =FORECAST(O$3,E46:N46,E$3:N$3) -> 6519.2032 | P46: =FORECAST(P$3,F46:O46,F$3:O$3) -> 6762.7107
B47: Total Non-Current Assets | C47: =SUM(C43:C46) -> 10252 | D47: =SUM(D43:D46) -> 10554 | E47: =SUM(E43:E46) -> 10482 | F47: =SUM(F43:F46) -> 11124 | G47: =SUM(G43:G46) -> 58932 | H47: =SUM(H43:H46) -> 60328 | I47: =SUM(I43:I46) -> 61069 | J47: =SUM(J43:J46) -> 63911 | ... P47: =SUM(P43:P46) -> 107896.74
B48: Receivables | C48: ='Data Sheet'!B67 -> 1085 | D48: ='Data Sheet'!C67 -> 1310 | E48: ='Data Sheet'!D67 -> 1816 | F48: ='Data Sheet'!E67 -> 1149 | G48: ='Data Sheet'!F67 -> 1758 | H48: ='Data Sheet'!G67 -> 2236 | I48: ='Data Sheet'!H67 -> 3079 | J48: ='Data Sheet'!I67 -> 2997 | ... L48: ='Data Sheet'!K67 -> 3379 | M48: =FORECAST(M$3,C48:L48,C$3:L$3) -> 3941.7874 | N48: =FORECAST(N$3,D48:M48,D$3:M$3) -> 4299.167 | O48: =FORECAST(O$3,E48:N48,E$3:N$3) -> 4669.1718 | P48: =FORECAST(P$3,F48:O48,F$3:O$3) -> 5122.9981
B49: Inventory | C49: ='Data Sheet'!B68 -> 2541 | D49: ='Data Sheet'!C68 -> 2513 | E49: ='Data Sheet'!D68 -> 2574 | F49: ='Data Sheet'!E68 -> 2767 | G49: ='Data Sheet'!F68 -> 3579 | H49: ='Data Sheet'!G68 -> 4096 | I49: ='Data Sheet'!H68 -> 4251 | J49: ='Data Sheet'!I68 -> 4022 | ... L49: ='Data Sheet'!K68 -> 4789 | M49: =FORECAST(M$3,C49:L49,C$3:L$3) -> 5079.5218 | N49: =FORECAST(N$3,D49:M49,D$3:M$3) -> 5419.0008 | O49: =FORECAST(O$3,E49:N49,E$3:N$3) -> 5717.6985 | P49: =FORECAST(P$3,F49:O49,F$3:O$3) -> 5958.5026
B50: Cash & Bank | C50: ='Data Sheet'!B69 -> 1828 | D50: ='Data Sheet'!C69 -> 3485 | E50: ='Data Sheet'!D69 -> 3757 | F50: ='Data Sheet'!E69 -> 5113 | G50: ='Data Sheet'!F69 -> 4471 | H50: ='Data Sheet'!G69 -> 3846 | I50: ='Data Sheet'!H69 -> 4678 | J50: ='Data Sheet'!I69 -> 7559 | ... L50: ='Data Sheet'!K69 -> 3248 | M50: =FORECAST(M$3,C50:L50,C$3:L$3) -> 6498.6198 | N50: =FORECAST(N$3,D50:M50,D$3:M$3) -> 6549.61 | O50: =FORECAST(O$3,E50:N50,E$3:N$3) -> 6751.4932 | P50: =FORECAST(P$3,F50:O50,F$3:O$3) -> 6902.4068
B51: Total Current Assets | C51: =SUM('Historical FS'!C48:C50) -> 5454 | D51: =SUM('Historical FS'!D48:D50) -> 7308 | E51: =SUM('Historical FS'!E48:E50) -> 8147 | F51: =SUM('Historical FS'!F48:F50) -> 9029 | G51: =SUM('Historical FS'!G48:G50) -> 9808 | H51: =SUM('Historical FS'!H48:H50) -> 10178 | I51: =SUM('Historical FS'!I48:I50) -> 12008 | J51: =SUM('Historical FS'!J48:J50) -> 14578 | ... P51: =SUM('Historical FS'!P48:P50) -> 17983.908
B53: Total Assets | C53: =SUM(C47,C51) -> 15706 | D53: =SUM(D47,D51) -> 17862 | E53: =SUM(E47,E51) -> 18629 | F53: =SUM(F47,F51) -> 20153 | G53: =SUM(G47,G51) -> 68740 | H53: =SUM(H47,H51) -> 70506 | I53: =SUM(I47,I51) -> 73077 | J53: =SUM(J47,J51) -> 78489 | ... P53: =SUM(P47,P51) -> 125880.64
B55: Shares Issued | C55: ='Data Sheet'!B70 -> 2164349639 | D55: ='Data Sheet'!C70 -> 2164528777 | E55: ='Data Sheet'!D70 -> 2164704405 | F55: ='Data Sheet'!E70 -> 2164704405 | G55: ='Data Sheet'!F70 -> 2349567819 | H55: ='Data Sheet'!G70 -> 2349591262 | I55: ='Data Sheet'!H70 -> 2349591262 | J55: ='Data Sheet'!I70 -> 2349591262 | ... L55: ='Data Sheet'!K70 -> 0 | M55: =FORECAST(M$3,C55:L55,C$3:L$3) -> 1.4839737e+09 | N55: =FORECAST(N$3,D55:M55,D$3:M$3) -> 1.2943858e+09 | O55: =FORECAST(O$3,E55:N55,E$3:N$3) -> 1.0743092e+09 | P55: =FORECAST(P$3,F55:O55,F$3:O$3) -> 8.2415866e+08
A58: # | B58: Cash Flow Statement
B59: Cash from Operating Activity
...

Sheet Ratio Analysis
B2: ="Ratio Analysis for "&'Data Sheet'!B1 -> Ratio Analysis for HINDUSTAN UNILEVER LTD
B3: Year | C3: ='Data Sheet'!B16 -> 42825 | D3: ='Data Sheet'!C16 -> 43190 | E3: ='Data Sheet'!D16 -> 43555 | F3: ='Data Sheet'!E16 -> 43921 | G3: ='Data Sheet'!F16 -> 44286 | H3: ='Data Sheet'!G16 -> 44651 | I3: ='Data Sheet'!H16 -> 45016 | J3: ='Data Sheet'!I16 -> 45382 | ... L3: ='Data Sheet'!K16 -> 46112 | M3: ='Data Sheet'!K56+365 -> 46477 | N3: =M3+365 -> 46842 | O3: =N3+365 -> 47207 | P3: =O3+365 -> 47572
B4: Profitability Ratios
B5: Gross Profit Margin | C5: ='Historical FS'!C12 -> 0.43685544 | D5: ='Historical FS'!D12 -> 0.45663244 | E5: ='Historical FS'!E12 -> 0.46372424 | F5: ='Historical FS'!F12 -> 0.48183898 | G5: ='Historical FS'!G12 -> 0.46200136 | H5: ='Historical FS'!H12 -> 0.44579186 | I5: ='Historical FS'!I12 -> 0.41596236 | J5: ='Historical FS'!J12 -> 0.45632997 | ... P5: ='Historical FS'!P12 -> 0.44669042
B6: EBITDA Margins | C6: ='Historical FS'!C17 -> 0.19082082 | D6: ='Historical FS'!D17 -> 0.21097201 | E6: ='Historical FS'!E17 -> 0.22589672 | F6: ='Historical FS'!F17 -> 0.24786969 | G6: ='Historical FS'!G17 -> 0.24721443 | H6: ='Historical FS'!H17 -> 0.24514739 | I6: ='Historical FS'!I17 -> 0.23352592 | J6: ='Historical FS'!J17 -> 0.23683275 | ... P6: ='Historical FS'!P17 -> 0.23681777
B7: EBIT Margins | C7: ='Historical FS'!C22 -> 0.17779386 | D7: ='Historical FS'!D22 -> 0.19634266 | E7: ='Historical FS'!E22 -> 0.21152379 | F7: ='Historical FS'!F22 -> 0.22268306 | G7: ='Historical FS'!G22 -> 0.22437697 | H7: ='Historical FS'!H22 -> 0.22434504 | I7: ='Historical FS'!I22 -> 0.21475735 | J7: ='Historical FS'!J22 -> 0.21718689 | ... P7: ='Historical FS'!P22 -> 0.21578549
B8: Net Profit Margins | C8: ='Historical FS'!C32 -> 0.11712201 | D8: ='Historical FS'!D32 -> 0.13712196 | E8: ='Historical FS'!E32 -> 0.14596795 | F8: ='Historical FS'!F32 -> 0.15916346 | G8: ='Historical FS'!G32 -> 0.16647529 | H8: ='Historical FS'!H32 -> 0.16537009 | I8: ='Historical FS'!I32 -> 0.16003632 | J8: ='Historical FS'!J32 -> 0.1529178 | ... P8: ='Historical FS'!P32 -> 0.15646291
B9: Return on Asset | C9: ='Historical FS'!C31/'Historical FS'!C53 -> 0.24729403 | D9: ='Historical FS'!D31/'Historical FS'!D53 -> 0.27286978 | E9: ='Historical FS'!E31/'Historical FS'!E53 -> 0.30801439 | F9: ='Historical FS'!F31/'Historical FS'!F53 -> 0.3141964 | G9: ='Historical FS'!G31/'Historical FS'!G53 -> 0.11389293 | H9: ='Historical FS'!H31/'Historical FS'!H53 -> 0.12301081 | I9: ='Historical FS'!I31/'Historical FS'!I53 -> 0.13266828 | J9: ='Historical FS'!J31/'Historical FS'!J53 -> 0.12059015 | ... P9: ='Historical FS'!P31/'Historical FS'!P53 -> 0.10453484
B10: Return on Equity | C10: ='Historical FS'!C31/SUM('Historical FS'!C35:C36) -> 0.57591934 | D10: ='Historical FS'!D31/SUM('Historical FS'!D35:D36) -> 0.66941354 | E10: ='Historical FS'!E31/SUM('Historical FS'!E35:E36) -> 0.72937587 | F10: ='Historical FS'!F31/SUM('Historical FS'!F35:F36) -> 0.76947381 | G10: ='Historical FS'!G31/SUM('Historical FS'!G35:G36) -> 0.16421949 | H10: ='Historical FS'!H31/SUM('Historical FS'!H35:H36) -> 0.17677993 | I10: ='Historical FS'!I31/SUM('Historical FS'!I35:I36) -> 0.19272821 | J10: ='Historical FS'!J31/SUM('Historical FS'!J35:J36) -> 0.18479831 | ... P10: ='Historical FS'!P31/SUM('Historical FS'!P35:P36) -> 0.16031727
B12: Solvency Ratios
B13: D/E Ratio | C13: ='Historical FS'!C37/SUM('Historical FS'!C35:C36) -> 0.041073547 | D13: ='Historical FS'!D37/SUM('Historical FS'!D35:D36) -> 0 | E13: ='Historical FS'!E37/SUM('Historical FS'!E35:E36) -> 0.012584213 | F13: ='Historical FS'!F37/SUM('Historical FS'!F35:F36) -> 0 | G13: ='Historical FS'!G37/SUM('Historical FS'!G35:G36) -> 0 | H13: ='Historical FS'!H37/SUM('Historical FS'!H35:H36) -> 0.021259249 | I13: ='Historical FS'!I37/SUM('Historical FS'!I35:I36) -> 0.024232665 | J13: ='Historical FS'!J37/SUM('Historical FS'!J35:J36) -> 0.028974189 | ... P13: ='Historical FS'!P37/SUM('Historical FS'!P35:P36) -> 0.033634908
B14: Debt Ratio | C14: ='Historical FS'!C37/'Historical FS'!C53 -> 0.017636572 | D14: ='Historical FS'!D37/'Historical FS'!D53 -> 0 | E14: ='Historical FS'!E37/'Historical FS'!E53 -> 0.0053142949 | F14: ='Historical FS'!F37/'Historical FS'!F53 -> 0 | G14: ='Historical FS'!G37/'Historical FS'!G53 -> 0 | H14: ='Historical FS'!H37/'Historical FS'!H53 -> 0.014793067 | I14: ='Historical FS'!I37/'Historical FS'!I53 -> 0.016681035 | J14: ='Historical FS'!J37/'Historical FS'!J53 -> 0.018907108 | ... P14: ='Historical FS'!P37/'Historical FS'!P53 -> 0.021931635
B15: Interest Coverage | C15: ='Historical FS'!C21/'Historical FS'!C24 -> 168.45714 | D15: ='Historical FS'!D21/'Historical FS'!D24 -> 268.42308 | E15: ='Historical FS'!E21/'Historical FS'!E24 -> 251.9697 | F15: ='Historical FS'!F21/'Historical FS'!F24 -> 75.076271 | G15: ='Historical FS'!G21/'Historical FS'!G24 -> 90.188034 | H15: ='Historical FS'!H21/'Historical FS'!H24 -> 111 | I15: ='Historical FS'!I21/'Historical FS'!I24 -> 114.12281 | J15: ='Historical FS'!J21/'Historical FS'!J24 -> 40.248503 | ... P15: ='Historical FS'!P21/'Historical FS'!P24 -> 30.329213
B17: Efficiency Ratios
B18: Asset Turnover | C18: ='Historical FS'!C6/'Historical FS'!C53 -> 2.1114224 | D18: ='Historical FS'!D6/'Historical FS'!D53 -> 1.9899787 | E18: ='Historical FS'!E6/'Historical FS'!E53 -> 2.1101508 | F18: ='Historical FS'!F6/'Historical FS'!F53 -> 1.9740485 | G18: ='Historical FS'!G6/'Historical FS'!G53 -> 0.68414315 | H18: ='Historical FS'!H6/'Historical FS'!H53 -> 0.74385159 | I18: ='Historical FS'!I6/'Historical FS'!I53 -> 0.8289886 | J18: ='Historical FS'!J6/'Historical FS'!J53 -> 0.78859458 | ... P18: ='Historical FS'!P6/'Historical FS'!P53 -> 0.6681126
B19: Inventory Turnover | C19: ='Historical FS'!C9/'Historical FS'!C49 -> 7.3494687 | D19: ='Historical FS'!D9/'Historical FS'!D49 -> 7.6856347 | E19: ='Historical FS'!E9/'Historical FS'!E49 -> 8.1899767 | F19: ='Historical FS'!F9/'Historical FS'!F49 -> 7.4499458 | G19: ='Historical FS'!G9/'Historical FS'!G49 -> 7.0692931 | H19: ='Historical FS'!H9/'Historical FS'!H49 -> 7.0961914 | I19: ='Historical FS'!I9/'Historical FS'!I49 -> 8.3229828 | J19: ='Historical FS'!J9/'Historical FS'!J49 -> 8.366733 | ... P19: ='Historical FS'!P9/'Historical FS'!P49 -> 7.8097957
B20: Receivable Turnover | C20: ='Historical FS'!C6/'Historical FS'!C48 -> 30.564055 | D20: ='Historical FS'!D6/'Historical FS'!D48 -> 27.133588 | E20: ='Historical FS'!E6/'Historical FS'!E48 -> 21.646476 | F20: ='Historical FS'!F6/'Historical FS'!F48 -> 34.624021 | G20: ='Historical FS'!G6/'Historical FS'!G48 -> 26.750853 | H20: ='Historical FS'!H6/'Historical FS'!H48 -> 23.455277 | I20: ='Historical FS'!I6/'Historical FS'!I48 -> 19.675219 | J20: ='Historical FS'!J6/'Historical FS'!J48 -> 20.652653 | ... P20: ='Historical FS'!P6/'Historical FS'!P48 -> 16.416646
B21: Payable Turnover | C21: ='Historical FS'!C6/'Historical FS'!C39 -> 5.3608147 | D21: ='Historical FS'!D6/'Historical FS'!D39 -> 4.9574616 | E21: ='Historical FS'!E6/'Historical FS'!E39 -> 5.4551762 | F21: ='Historical FS'!F6/'Historical FS'!F39 -> 5.2797611 | G21: ='Historical FS'!G6/'Historical FS'!G39 -> 5.3428766 | H21: ='Historical FS'!H6/'Historical FS'!H39 -> 5.7836348 | I21: ='Historical FS'!I6/'Historical FS'!I39 -> 6.3275538 | J21: ='Historical FS'!J6/'Historical FS'!J39 -> 5.9027274 | ... P21: ='Historical FS'!P6/'Historical FS'!P39 -> 5.442483
B22: Fixed Asset Turnover | C22: ='Historical FS'!C6/'Historical FS'!C43 -> 7.5044128 | D22: ='Historical FS'!D6/'Historical FS'!D43 -> 7.8500442 | E22: ='Historical FS'!E6/'Historical FS'!E43 -> 8.3372216 | F22: ='Historical FS'!F6/'Historical FS'!F43 -> 7.2609965 | G22: ='Historical FS'!G6/'Historical FS'!G43 -> 0.91417686 | H22: ='Historical FS'!H6/'Historical FS'!H43 -> 1.0189031 | I22: ='Historical FS'!I6/'Historical FS'!I43 -> 1.1500057 | J22: ='Historical FS'!J6/'Historical FS'!J43 -> 1.151682 | ... P22: ='Historical FS'!P6/'Historical FS'!P43 -> 0.89294409
B24: Liquidity Ratios
B25: Current Ratio | C25: ='Historical FS'!C51/SUM('Historical FS'!C37,'Historical FS'!C39) -> 0.84388055 | D25: ='Historical FS'!D51/SUM('Historical FS'!D37,'Historical FS'!D39) -> 1.0192469 | E25: ='Historical FS'!E51/SUM('Historical FS'!E37,'Historical FS'!E39) -> 1.1152635 | F25: ='Historical FS'!F51/SUM('Historical FS'!F37,'Historical FS'!F39) -> 1.1982747 | G25: ='Historical FS'!G51/SUM('Historical FS'!G37,'Historical FS'!G39) -> 1.1142922 | H25: ='Historical FS'!H51/SUM('Historical FS'!H37,'Historical FS'!H39) -> 1.0066264 | I25: ='Historical FS'!I51/SUM('Historical FS'!I37,'Historical FS'!I39) -> 1.112573 | J25: ='Historical FS'!J51/SUM('Historical FS'!J37,'Historical FS'!J39) -> 1.217878 | ... P25: ='Historical FS'!P51/SUM('Historical FS'!P37,'Historical FS'!P39) -> 0.98738228
B26: Quick Ratio | C26: =('Historical FS'!C51-'Historical FS'!C49)/SUM('Historical FS'!C39,'Historical FS'!C37) -> 0.45071948 | D26: =('Historical FS'!D51-'Historical FS'!D49)/SUM('Historical FS'!D39,'Historical FS'!D37) -> 0.66875872 | E26: =('Historical FS'!E51-'Historical FS'!E49)/SUM('Historical FS'!E39,'Historical FS'!E37) -> 0.76290212 | F26: =('Historical FS'!F51-'Historical FS'!F49)/SUM('Historical FS'!F39,'Historical FS'!F37) -> 0.83105508 | G26: =('Historical FS'!G51-'Historical FS'!G49)/SUM('Historical FS'!G39,'Historical FS'!G37) -> 0.70768007 | H26: =('Historical FS'!H51-'Historical FS'!H49)/SUM('Historical FS'!H39,'Historical FS'!H37) -> 0.60152309 | I26: =('Historical FS'!I51-'Historical FS'!I49)/SUM('Historical FS'!I39,'Historical FS'!I37) -> 0.71870657 | J26: =('Historical FS'!J51-'Historical FS'!J49)/SUM('Historical FS'!J39,'Historical FS'!J37) -> 0.88187135 | ... P26: =('Historical FS'!P51-'Historical FS'!P49)/SUM('Historical FS'!P39,'Historical FS'!P37) -> 0.6602387
B27: Cash Ratio | C27: ='Historical FS'!C50/SUM('Historical FS'!C39,'Historical FS'!C37) -> 0.28284079 | D27: ='Historical FS'!D50/SUM('Historical FS'!D39,'Historical FS'!D37) -> 0.486053 | E27: ='Historical FS'!E50/SUM('Historical FS'!E39,'Historical FS'!E37) -> 0.51430527 | F27: ='Historical FS'!F50/SUM('Historical FS'!F39,'Historical FS'!F37) -> 0.67856669 | G27: ='Historical FS'!G50/SUM('Historical FS'!G39,'Historical FS'!G37) -> 0.50795274 | H27: ='Historical FS'!H50/SUM('Historical FS'!H39,'Historical FS'!H37) -> 0.38037781 | I27: ='Historical FS'!I50/SUM('Historical FS'!I39,'Historical FS'!I37) -> 0.43342907 | J27: ='Historical FS'!J50/SUM('Historical FS'!J39,'Historical FS'!J37) -> 0.63149541 | ... P27: ='Historical FS'!P50/SUM('Historical FS'!P39,'Historical FS'!P37) -> 0.37896737
B29: Market Ratios
B30: Earning per share | C30: ='Historical FS'!C6/'Data Sheet'!B124 -> 153.22275 | D30: ='Historical FS'!D6/'Data Sheet'!C124 -> 164.21806 | E30: ='Historical FS'!E6/'Data Sheet'!D124 -> 181.5956 | F30: ='Historical FS'!F6/'Data Sheet'!E124 -> 183.77217 | G30: ='Historical FS'!G6/'Data Sheet'!F124 -> 200.15322 | H30: ='Historical FS'!H6/'Data Sheet'!G124 -> 223.21246 | I30: ='Historical FS'!I6/'Data Sheet'!H124 -> 257.83112 | J30: ='Historical FS'!J6/'Data Sheet'!I124 -> 263.43207 | ... L30: ='Historical FS'!L6/'Data Sheet'!K124 -> 274.37862 | M30: =FORECAST(M$3,C30:L30,C$3:L$3) -> 299.5555 | N30: =FORECAST(N$3,D30:M30,D$3:M$3) -> 315.53373 | O30: =FORECAST(O$3,E30:N30,E$3:N$3) -> 331.08567 | P30: =FORECAST(P$3,F30:O30,F$3:O$3) -> 347.41062
B31: P/E Ratio | C31: ='Data Sheet'!B121/'Ratio Analysis'!C30 -> 5.695042 | D31: ='Data Sheet'!C121/'Ratio Analysis'!D30 -> 7.770826 | E31: ='Data Sheet'!D121/'Ratio Analysis'!E30 -> 8.9954271 | F31: ='Data Sheet'!E121/'Ratio Analysis'!F30 -> 11.970419 | G31: ='Data Sheet'!F121/'Ratio Analysis'!G30 -> 11.626693 | H31: ='Data Sheet'!G121/'Ratio Analysis'!H30 -> 8.7840078 | I31: ='Data Sheet'!H121/'Ratio Analysis'!I30 -> 9.5040506 | J31: ='Data Sheet'!I121/'Ratio Analysis'!J30 -> 8.2265609 | ... L31: ='Data Sheet'!K121/'Ratio Analysis'!L30 -> 7.4903796 | M31: =FORECAST(M$3,C31:L31,C$3:L$3) -> 8.9447722 | N31: =FORECAST(N$3,D31:M31,D$3:M$3) -> 8.1676671 | O31: =FORECAST(O$3,E31:N31,E$3:N$3) -> 7.4163617 | P31: =FORECAST(P$3,F31:O31,F$3:O$3) -> 6.6642982
B32: Book Value per share | C32: =SUM('Historical FS'!C35:C36)/'Data Sheet'!B124 -> 31.16019 | D32: =SUM('Historical FS'!D35:D36)/'Data Sheet'!C124 -> 33.638254 | E32: =SUM('Historical FS'!E35:E36)/'Data Sheet'!D124 -> 36.342218 | F32: =SUM('Historical FS'!F35:F36)/'Data Sheet'!E124 -> 38.012749 | G32: =SUM('Historical FS'!G35:G36)/'Data Sheet'!F124 -> 202.90262 | H32: =SUM('Historical FS'!H35:H36)/'Data Sheet'!G124 -> 208.80575 | I32: =SUM('Historical FS'!I35:I36)/'Data Sheet'!H124 -> 214.09602 | J32: =SUM('Historical FS'!J35:J36)/'Data Sheet'!I124 -> 217.98604 | ... L32: =SUM('Historical FS'!L35:L36)/'Data Sheet'!K124 -> 207.43531 | M32: =FORECAST(M$3,C32:L32,C$3:L$3) -> 282.20645 | N32: =FORECAST(N$3,D32:M32,D$3:M$3) -> 310.01233 | O32: =FORECAST(O$3,E32:N32,E$3:N$3) -> 332.87593 | P32: =FORECAST(P$3,F32:O32,F$3:O$3) -> 347.1867
B34: Operating Cycle Ratios
B35: (in days)
B36: Inventory Days | C36: =365/C19 -> 49.663454 | D36: =365/D19 -> 47.491198 | E36: =365/E19 -> 44.566671 | F36: =365/F19 -> 48.993645 | G36: =365/G19 -> 51.631754 | H36: =365/H19 -> 51.436042 | I36: =365/I19 -> 43.85447 | J36: =365/J19 -> 43.625152 | ... P36: =365/P19 -> 46.736178
B37: Receivable Days | C37: =365/C20 -> 11.942133 | D37: =365/D20 -> 13.451962 | E37: =365/E20 -> 16.861867 | F37: =365/F20 -> 10.541814 | G37: =365/G20 -> 13.644425 | H37: =365/H20 -> 15.56153 | I37: =365/I20 -> 18.551255 | J37: =365/J20 -> 17.673275 | ... P37: =365/P20 -> 22.233531
B38: Payable Days | C38: =365/C21 -> 68.086665 | D38: =365/D21 -> 73.626389 | E38: =365/E21 -> 66.908929 | F38: =365/F21 -> 69.131916 | G38: =365/G21 -> 68.315259 | H38: =365/H21 -> 63.109103 | I38: =365/I21 -> 57.684219 | J38: =365/J21 -> 61.835821 | ... P38: =365/P21 -> 67.064978
B40: Cash Conversion Cycle | C40: =SUM(C36:C37)-C38 -> -6.4810791 | D40: =SUM(D36:D37)-D38 -> -12.683229 | E40: =SUM(E36:E37)-E38 -> -5.4803904 | F40: =SUM(F36:F37)-F38 -> -9.5964562 | G40: =SUM(G36:G37)-G38 -> -3.0390807 | H40: =SUM(H36:H37)-H38 -> 3.8884694 | I40: =SUM(I36:I37)-I38 -> 4.7215052 | J40: =SUM(J36:J37)-J38 -> -0.53739455 | ... P40: =SUM(P36:P37)-P38 -> 1.9047315

Sheet DCF Modelling
B2: ="WACC Calculation for "&'Data Sheet'!B1 -> WACC Calculation for HINDUSTAN UNILEVER LTD | E2: ="Discounted Cash Flow Statement for "&'Data Sheet'!B1 -> Discounted Cash Flow Statement for HINDUSTAN UNILEVER LTD
F3: 1 | G3: 2 | H3: 3 | I3: 4 | J3: 5 | K3: 6 | L3: 7 | M3: 8 | N3: 9 | O3: 10
B4: Equity (E) | C4: ='Data Sheet'!B9/100 -> 5166.8609
B5: Debt (D) | C5: 1478 | E5: EBIT | F5: ='Historical FS'!C21 -> 5896 | G5: ='Historical FS'!D21 -> 6979 | H5: ='Historical FS'!E21 -> 8315 | I5: ='Historical FS'!F21 -> 8859 | J5: ='Historical FS'!G21 -> 10552 | K5: ='Historical FS'!H21 -> 11766 | L5: ='Historical FS'!I21 -> 13010 | M5: ='Historical FS'!J21 -> 13443 | ... O5: ='Historical FS'!L21 -> 13706
B6: Rf | C6: 0.0702 | E6: Tax Rate | F6: =$C$10 -> 0.23766546 | G6: =$C$10 -> 0.23766546 | H6: =$C$10 -> 0.23766546 | I6: =$C$10 -> 0.23766546 | J6: =$C$10 -> 0.23766546 | K6: =$C$10 -> 0.23766546 | L6: =$C$10 -> 0.23766546 | M6: =$C$10 -> 0.23766546 | ... O6: =$C$10 -> 0.23766546
B7: Equity Risk Premium (ERP) | C7: 0.0418 | E7: Depreciation | F7: ='Historical FS'!C19 -> 432 | G7: ='Historical FS'!D19 -> 520 | H7: ='Historical FS'!E19 -> 565 | I7: ='Historical FS'!F19 -> 1002 | J7: ='Historical FS'!G19 -> 1074 | K7: ='Historical FS'!H19 -> 1091 | L7: ='Historical FS'!I19 -> 1137 | M7: ='Historical FS'!J19 -> 1216 | ... O7: ='Historical FS'!L19 -> 1333
B8: Rm | C8: =C6+(C9*C7) -> 0.102386 | E8: CapEx | F8: ='Historical FS'!C74 -> -1113 | G8: ='Historical FS'!D74 -> -895 | H8: ='Historical FS'!E74 -> -767 | I8: ='Historical FS'!F74 -> -862 | J8: ='Historical FS'!G74 -> -4613 | K8: ='Historical FS'!H74 -> -1228 | L8: ='Historical FS'!I74 -> -1192 | M8: ='Historical FS'!J74 -> -1477 | ... O8: ='Historical FS'!L74 -> -1360
B9: Beta | C9: 0.77 | E9: Non-Cash WC | F9: ='Historical FS'!C48+'Historical FS'!C49-'Historical FS'!C39 -> -2560 | G9: ='Historical FS'!D48+'Historical FS'!D49-'Historical FS'!D39 -> -3347 | H9: ='Historical FS'!E48+'Historical FS'!E49-'Historical FS'!E39 -> -2816 | I9: ='Historical FS'!F48+'Historical FS'!F49-'Historical FS'!F39 -> -3619 | J9: ='Historical FS'!G48+'Historical FS'!G49-'Historical FS'!G39 -> -3465 | K9: ='Historical FS'!H48+'Historical FS'!H49-'Historical FS'!H39 -> -2736 | L9: ='Historical FS'!I48+'Historical FS'!I49-'Historical FS'!I39 -> -2244 | M9: ='Historical FS'!J48+'Historical FS'!J49-'Historical FS'!J39 -> -3467 | ... O9: ='Historical FS'!L48+'Historical FS'!L49-'Historical FS'!L39 -> -5157
